2025-01-14 13:12:08.448073: I tensorflow/core/util/port.cc:153] oneDNN custom operations are on. You may see slightly different numerical results due to floating-point round-off errors from different computation orders. To turn them off, set the environment variable `TF_ENABLE_ONEDNN_OPTS=0`.
2025-01-14 13:12:08.463138: E external/local_xla/xla/stream_executor/cuda/cuda_fft.cc:485] Unable to register cuFFT factory: Attempting to register factory for plugin cuFFT when one has already been registered
2025-01-14 13:12:08.483789: E external/local_xla/xla/stream_executor/cuda/cuda_dnn.cc:8454] Unable to register cuDNN factory: Attempting to register factory for plugin cuDNN when one has already been registered
2025-01-14 13:12:08.490031: E external/local_xla/xla/stream_executor/cuda/cuda_blas.cc:1452] Unable to register cuBLAS factory: Attempting to register factory for plugin cuBLAS when one has already been registered
2025-01-14 13:12:08.505001: I tensorflow/core/platform/cpu_feature_guard.cc:210] This TensorFlow binary is optimized to use available CPU instructions in performance-critical operations.
To enable the following instructions: AVX2 AVX512F AVX512_VNNI FMA, in other operations, rebuild TensorFlow with the appropriate compiler flags.
2025-01-14 13:12:09.626628: W tensorflow/compiler/tf2tensorrt/utils/py_utils.cc:38] TF-TRT Warning: Could not find TensorRT
/usr/local/lib/python3.10/dist-packages/albumentations/__init__.py:13: UserWarning: A new version of Albumentations is available: 2.0.0 (you have 1.4.15). Upgrade using: pip install -U albumentations. To disable automatic update checks, set the environment variable NO_ALBUMENTATIONS_UPDATE to 1.
  check_for_updates()
Starting the main process
runtime_choices: {'exp': '201_3dcnnbase', 'dir': 'local', 'hydra/env': 'default', 'hydra/callbacks': None, 'hydra/job_logging': 'none', 'hydra/hydra_logging': 'default', 'hydra/hydra_help': 'default', 'hydra/help': 'default', 'hydra/sweeper': 'basic', 'hydra/launcher': 'basic', 'hydra/output': 'default'}
exp_name: 201_3dcnnbase
ouput_path: /kaggle/working/output/experiments
########## current cfg ##########
debug: false
work_dir: /kaggle/working
dir:
  input_dir: ${work_dir}/input
  output_dir: ${work_dir}/output
  exp_dir: ${work_dir}/output/experiments
  TRAIN_DATA_DIR: ${work_dir}/input/czii-only-kaggle-data-npy
  TEST_DATA_DIR: ${work_dir}/input/czii-cryo-et-object-identification
exp:
  seed: 634
  STRIDE: 16
  NUM_SLICE: 32
  IMAGE_SIZE: 512
  NUM_WORKERS: 4
  BATCH_SIZE: 2
  PRETRAIN: true
  model:
    name: UMC
    n_channels: 1
    n_classes: 7
    lr: 0.001
    arch: tf_efficientnet_b4.ns_jft_in1k
    n_frames: 184
  logger:
    wandb:
      experiment_name: CZII
      run_name: 201_3dcnnbase
      tracking_uri: file:${work_dir}/mlruns
  trainer:
    max_epochs: 30
    log_every_n_steps: 100
    val_check_interval: 1.0
    gpus: 4
    accumulate_grad_batches: 1
    precision: 16
    gradient_clip_val: 1.0
    patience: 10
    strategy: ddp
  USE_CALLBACK: true
  target_size: (184, 128, 128)
  overlap: 0.75
  patch_size: 64

########################################
seve cfg done. save path: /kaggle/working/output/experiments/201_3dcnnbase.yaml
[2025-01-14 13:12:14,215][HYDRA] Seed set to 634
Number of GPUs available: 4, current GPU:0
[0, 1, 2, 3]
[2025-01-14 13:12:15,316][HYDRA] git root error: Cmd('git') failed due to: exit code(128)
  cmdline: git rev-parse --show-toplevel
  stderr: 'fatal: detected dubious ownership in repository at '/kaggle/working'
To add an exception for this directory, call:

	git config --global --add safe.directory /kaggle/working'
wandb: Using wandb-core as the SDK backend.  Please refer to https://wandb.me/wandb-core for more information.
wandb: WARNING Path /kaggle/working/output/experiments/wandb_logs/201_3dcnnbase/wandb/ wasn't writable, using system temp directory.
Error executing job with overrides: ['exp=201_3dcnnbase']
Traceback (most recent call last):
  File "/kaggle/working/experiments/train.py", line 157, in main
    wandb_logger.log_hyperparams(cfg)
  File "/usr/local/lib/python3.10/dist-packages/lightning_utilities/core/rank_zero.py", line 42, in wrapped_fn
    return fn(*args, **kwargs)
  File "/usr/local/lib/python3.10/dist-packages/lightning/pytorch/loggers/wandb.py", line 429, in log_hyperparams
    self.experiment.config.update(params, allow_val_change=True)
  File "/usr/local/lib/python3.10/dist-packages/lightning/fabric/loggers/logger.py", line 118, in experiment
    return fn(self)
  File "/usr/local/lib/python3.10/dist-packages/lightning/pytorch/loggers/wandb.py", line 407, in experiment
    self._experiment = wandb.init(**self._wandb_init)
  File "/usr/local/lib/python3.10/dist-packages/wandb/sdk/wandb_init.py", line 1312, in init
    wandb._sentry.reraise(e)
  File "/usr/local/lib/python3.10/dist-packages/wandb/analytics/sentry.py", line 156, in reraise
    raise exc.with_traceback(sys.exc_info()[2])
  File "/usr/local/lib/python3.10/dist-packages/wandb/sdk/wandb_init.py", line 1290, in init
    wi.setup(
  File "/usr/local/lib/python3.10/dist-packages/wandb/sdk/wandb_init.py", line 289, in setup
    wandb_login._login(
  File "/usr/local/lib/python3.10/dist-packages/wandb/sdk/wandb_login.py", line 337, in _login
    wlogin.prompt_api_key()
  File "/usr/local/lib/python3.10/dist-packages/wandb/sdk/wandb_login.py", line 271, in prompt_api_key
    raise UsageError("api_key not configured (no-tty). call " + directive)
wandb.errors.errors.UsageError: api_key not configured (no-tty). call wandb.login(key=[your_api_key])

Set the environment variable HYDRA_FULL_ERROR=1 for a complete stack trace.
